<mujoco model="panda">
  <compiler angle="radian" autolimits="true"/>

  <option integrator="implicitfast"/>

  <default>
    <default class="panda">
      <material specular="0.5" shininess="0.25"/>
      <joint armature="0.1" damping="1" axis="0 0 1" range="-2.8973 2.8973"/>
      <general dyntype="none" biastype="affine" ctrlrange="-2.8973 2.8973" forcerange="-87 87"/>
      <default class="finger">
        <joint axis="0 1 0" type="slide" range="0 0.04"/>
      </default>

      <default class="visual">
        <geom type="mesh" contype="0" conaffinity="0" group="2"/>
      </default>
      <default class="collision">
        <geom type="mesh" group="3"/>
        <default class="fingertip_pad_collision_1">
          <geom type="box" size="0.0085 0.004 0.0085" pos="0 0.0055 0.0445"/>
        </default>
        <default class="fingertip_pad_collision_2">
          <geom type="box" size="0.003 0.002 0.003" pos="0.0055 0.002 0.05"/>
        </default>
        <default class="fingertip_pad_collision_3">
          <geom type="box" size="0.003 0.002 0.003" pos="-0.0055 0.002 0.05"/>
        </default>
        <default class="fingertip_pad_collision_4">
          <geom type="box" size="0.003 0.002 0.0035" pos="0.0055 0.002 0.0395"/>
        </default>
        <default class="fingertip_pad_collision_5">
          <geom type="box" size="0.003 0.002 0.0035" pos="-0.0055 0.002 0.0395"/>
        </default>
      </default>
    </default>
  </default>

  <asset>
    <material class="panda" name="white" rgba="1 1 1 1"/>
    <material class="panda" name="off_white" rgba="0.901961 0.921569 0.929412 1"/>
    <material class="panda" name="panda_black" rgba="0.25 0.25 0.25 1"/>
    <material class="panda" name="green" rgba="0 1 0 1"/>
    <material class="panda" name="light_blue" rgba="0.039216 0.541176 0.780392 1"/>

    <!-- Collision meshes -->
    <mesh name="hand_c" file="assets/hand.stl"/>

    <!-- Visual meshes -->
    <mesh file="assets/hand_0.obj"/>
    <mesh file="assets/hand_1.obj"/>
    <mesh file="assets/hand_2.obj"/>
    <mesh file="assets/hand_3.obj"/>
    <mesh file="assets/hand_4.obj"/>
    <mesh file="assets/finger_0.obj"/>
    <mesh file="assets/finger_1.obj"/>
  </asset>

  <worldbody>

    <body name="floating_1" mocap="true" pos="0 -0.5 0.2" euler="0 0 0">
      <geom name="floating_1" type="sphere" group="1" size="0.02" rgba="0.1 0.1 0.1 0.2" class="visual"/>
      <site name="mocap" pos="0 0 0" euler="0 0 0" size="0.01" rgba="0.1 0.1 0.1 0.2"/>
    </body>

    <body name="floating_2" pos="0 -0.5 0.2" euler="0 0 1.570795">
      <geom name="floating_2" type="sphere" group="1" size="0.02" rgba="0.2 0.2 0.2 1" class="visual"/>
      <freejoint name="floating_2"/>

      <body name="hand" pos="0 0 0" euler="0 0 0">
        <inertial mass="0.73" pos="-0.01 0 0.03" diaginertia="0.001 0.0025 0.0017"/>
        <geom mesh="hand_0" material="off_white" class="visual"/>
        <geom mesh="hand_1" material="panda_black" class="visual"/>
        <geom mesh="hand_2" material="panda_black" class="visual"/>
        <geom mesh="hand_3" material="white" class="visual"/>
        <geom mesh="hand_4" material="off_white" class="visual"/>
        <geom mesh="hand_c" class="collision"/>
        <body name="left_finger" pos="0 0 0.0584">
          <inertial mass="0.015" pos="0 0 0" diaginertia="2.375e-6 2.375e-6 7.5e-7"/>
          <joint name="finger_joint1" class="finger"/>
          <geom mesh="finger_0" material="off_white" class="visual"/>
          <geom mesh="finger_1" material="panda_black" class="visual"/>
          <geom mesh="finger_0" class="collision"/>
          <geom class="fingertip_pad_collision_1"/>
          <geom class="fingertip_pad_collision_2"/>
          <geom class="fingertip_pad_collision_3"/>
          <geom class="fingertip_pad_collision_4"/>
          <geom class="fingertip_pad_collision_5"/>
        </body>
        <body name="right_finger" pos="0 0 0.0584" quat="0 0 0 1">
          <inertial mass="0.015" pos="0 0 0" diaginertia="2.375e-6 2.375e-6 7.5e-7"/>
          <joint name="finger_joint2" class="finger"/>
          <geom mesh="finger_0" material="off_white" class="visual"/>
          <geom mesh="finger_1" material="panda_black" class="visual"/>
          <geom mesh="finger_0" class="collision"/>
          <geom class="fingertip_pad_collision_1"/>
          <geom class="fingertip_pad_collision_2"/>
          <geom class="fingertip_pad_collision_3"/>
          <geom class="fingertip_pad_collision_4"/>
          <geom class="fingertip_pad_collision_5"/>
        </body>
      </body>
    </body>
  </worldbody>

  <tendon>
    <fixed name="split">
      <joint joint="finger_joint1" coef="0.5"/>
      <joint joint="finger_joint2" coef="0.5"/>
    </fixed>
  </tendon>

  <equality>
    <joint joint1="finger_joint1" joint2="finger_joint2" solimp="0.95 0.99 0.001" solref="0.005 1"/>

    <weld body1="floating_1" body2="floating_2" solimp="0.95 0.99 0.001 0.5 2"  solref="0.02 1"/>

  </equality>



  <actuator>
    <general class="panda" name="panda_actuator" tendon="split" forcerange="-100 100" ctrlrange="0 255"
      gainprm="0.01568627451 0 0" biasprm="0 -100 -10"/>
  </actuator>

  <keyframe>
    <key name="home" qpos="0 -0.5 0.2 0 0 0 1 0.04 0.04" ctrl="255" mpos="0 -0.5 0.2" mquat="0 0 0 1"/>
  </keyframe>

</mujoco>
